* thread #1, queue = 'com.apple.main-thread', stop reason = EXC_BAD_ACCESS (code=1, address=0x50)
  * frame #0: 0x00000001003f3fc1 libpython3.6m.dylib`PyErr_FormatV [inlined] PyErr_Restore at errors.c:42 [opt]
    frame #1: 0x00000001003f3fb7 libpython3.6m.dylib`PyErr_FormatV [inlined] PyErr_Clear at errors.c:355 [opt]
    frame #2: 0x00000001003f3fb7 libpython3.6m.dylib`PyErr_FormatV(exception=0x00000001004cba18, format="%s:%d: bad argument to internal function", vargs=0x00007fff5fbfdcb0) at errors.c:841 [opt]
    frame #3: 0x00000001003f2c39 libpython3.6m.dylib`PyErr_Format(exception=<unavailable>, format=<unavailable>) at errors.c:860 [opt]
    frame #4: 0x0000000100358220 libpython3.6m.dylib`PyModule_GetDict(m=0x0000000101a5a868) at moduleobject.c:450 [opt]
    frame #5: 0x00000001000f491c _locale.so`init_locale at _localemodule.c:703 [opt]
    frame #6: 0x00000001018d1176 libpython2.7.dylib`_PyImport_LoadDynamicModule(name="_locale", pathname=".../lib/python2.7/lib-dynload/_locale.so", fp=<unavailable>) at importdl.c:53 [opt]
