bool throwing_func()
{
    // something is wrong...
    throw char('5');

    // ...

    return true;
}

void exception_handler(std::exception_ptr _Eptr)
{
    try 
    {
        if (_Eptr) {std::rethrow_exception(_Eptr);}
    }


    catch(int _Xi)
    {
        std::cout << ""int\n"";
    }

    catch(char _Xc)
    {
        std::cout << ""char\n"";
    }

    catch(const std::exception& _Xe)
    {
       std::cout << ""std::exception "" << _Xe.what() << ""\n"";
    }

    catch (...)
    {// develop more catch cases above to avoid what follows
        std::cout << ""unhandled exception\n"";
        // grande problema
    }
}

int main()
{

    try
    {
        throwing_func();
    }

    catch(...)
    {
        //Determine exception type here

         exception_handler(std::current_exception());
    }

    return 0;
}
