#0  PyErr_Restore () at /usr/src/debug/Python-2.7.14/Python/errors.c:39
#1  0x00007ffff7aa1a9f in PyErr_SetString () at /usr/src/debug/Python-2.7.14/Python/errors.c:70
#2  0x00007fffefa1e67f in raise_error () from /tmp/libpyerr.so
#3  0x00007fffefe30bde in ffi_call_unix64 () at ../src/x86/unix64.S:76
#4  0x00007fffefe3054f in ffi_call (cif=cif@entry=0x7fffffffd7f0, fn=fn@entry=0x7fffefa1e65a <raise_error>, rvalue=<optimized out>, rvalue@entry=0x7fffffffd760, avalue=avalue@entry=0x7fffffffd750) at ../src/x86/ffi64.c:525
#5  0x00007ffff00433a5 in _call_function_pointer (argcount=0, resmem=0x7fffffffd760, restype=<optimized out>, atypes=<optimized out>, avalues=0x7fffffffd750, pProc=0x7fffefa1e65a <raise_error>, flags=4353) at /usr/src/debug/Python-2.7.14/Modules/_ctypes/callproc.c:841
#6  _ctypes_callproc (pProc=pProc@entry=0x7fffefa1e65a <raise_error>, argtuple=argtuple@entry=(), flags=4353, argtypes=argtypes@entry=(), restype=<_ctypes.PyCSimpleType at remote 0x55555580f2d0>, checker=0x0) at /usr/src/debug/Python-2.7.14/Modules/_ctypes/callproc.c:1184
#7  0x00007ffff003d0be in PyCFuncPtr_call (self=self@entry=0x7ffff7fe8ef0, inargs=<optimized out>, kwds=<optimized out>) at /usr/src/debug/Python-2.7.14/Modules/_ctypes/_ctypes.c:3979
#8  0x00007ffff7a34ca3 in PyObject_Call () at /usr/src/debug/Python-2.7.14/Objects/abstract.c:2547
#9  0x00007ffff7af93e2 in do_call (nk=<optimized out>, na=<optimized out>, pp_stack=0x7fffffffd9d8, func=<_FuncPtr(__name__='raise_error') at remote 0x7ffff7fe8ef0>) at /usr/src/debug/Python-2.7.14/Python/ceval.c:4651
