Exception happened during processing of request from ('127.0.0.1', 50707)
Traceback (most recent call last):
  File "C:\Python27\lib\SocketServer.py", line 290, in _handle_request_noblock
    self.process_request(request, client_address)
  File "C:\Python27\lib\SocketServer.py", line 318, in process_request
    self.finish_request(request, client_address)
  File "C:\Python27\lib\SocketServer.py", line 331, in finish_request
    self.RequestHandlerClass(request, client_address, self)
  File "C:\Python27\lib\SocketServer.py", line 654, in __init__
    self.finish()
  File "C:\Python27\lib\SocketServer.py", line 713, in finish
    self.wfile.close()
  File "C:\Python27\lib\socket.py", line 283, in close
    self.flush()
  File "C:\Python27\lib\socket.py", line 307, in flush
    self._sock.sendall(view[write_offset:write_offset+buffer_size])
error: [Errno 10053] Eine bestehende Verbindung wurde softwaregesteuert
durch den Hostcomputer abgebrochen
