In [78]: class WithException:
    ...:     
    ...:     def __enter__(self):
    ...:         pass
    ...:     def __exit__(self, exc, msg, traceback):
    ...:         if exc is OtherException:
    ...:             raise MyException(msg)
    ...:         

In [79]: with WithException():
    ...:     raise OtherException('aaaaaaarrrrrrggggh')
    ...: 
---------------------------------------------------------------------------
OtherException                            Traceback (most recent call last)
<ipython-input-79-a0a23168647e> in <module>()
      1 with WithException():
----> 2     raise OtherException('aaaaaaarrrrrrggggh')

OtherException: aaaaaaarrrrrrggggh

During handling of the above exception, another exception occurred:

MyException                               Traceback (most recent call last)
<ipython-input-79-a0a23168647e> in <module>()
      1 with WithException():
----> 2     raise OtherException('aaaaaaarrrrrrggggh')

<ipython-input-78-dba8b409a6fd> in __exit__(self, exc, msg, traceback)
      5     def __exit__(self, exc, msg, traceback):
      6         if exc is OtherException:
----> 7             raise MyException(msg)
      8 

MyException: aaaaaaarrrrrrggggh
