Traceback (most recent call last):
  File ""C:\Users\5V\AppData\Local\Programs\Python\Python35\lib\inspect.py"", line 1089, in getfullargspec
    sigcls=Signature)
  File ""C:\Users\5V\AppData\Local\Programs\Python\Python35\lib\inspect.py"", line 2156, in _signature_from_callable
    raise TypeError('{!r} is not a callable object'.format(obj))
TypeError: array([0, 0, 0, 0, 0, 1, 0, 0, 0, 0, 0, 0, 0, 0, 0, 0, 0, 0, 0, 0, 0, 0,
       0, 0, 0, 1, 0, 0, 0, 0, 0, 0, 0, 0, 0, 0, 0, 0, 0, 1, 0, 0, 0, 0,
       0, 0, 0, 0, 0, 0, 0, 0, 0, 0, 0, 0, 0, 0, 0, 0, 0, 0, 0, 0, 0, 0,
       0, 0, 0, 0, 0, 0, 0, 0, 0, 0, 0, 0, 0, 0, 0, 0, 0, 0, 0, 0, 0, 0,
       0, 0, 0, 0, 0, 0, 0, 0, 0, 0, 0, 0, 0, 0, 0, 0, 0, 0, 0, 0, 0, 1,
       0, 0, 0, 0, 0, 0, 0, 0, 0, 0, 0, 0, 0, 0, 0, 0, 0, 0, 0, 0, 0, 0,
       0, 0, 0, 0, 0, 0, 0, 0, 0, 0, 0, 0, 0, 0, 0, 0, 0, 0, 0, 0, 0, 0,
       0, 0, 0, 0, 0, 0, 1, 0, 0]) is not a callable object

The above exception was the direct cause of the following exception:

Traceback (most recent call last):
  File ""C:/Users/5V/PycharmProjects/UberAPI/deep_learning.py"", line 41, in <module>
    print(list(prediction))
  File ""C:\Users\5V\AppData\Local\Programs\Python\Python35\lib\site-packages\tensorflow\python\estimator\estimator.py"", line 486, in predict
    input_fn, model_fn_lib.ModeKeys.PREDICT)
  File ""C:\Users\5V\AppData\Local\Programs\Python\Python35\lib\site-packages\tensorflow\python\estimator\estimator.py"", line 662, in _get_features_from_input_fn
    result = self._call_input_fn(input_fn, mode)
  File ""C:\Users\5V\AppData\Local\Programs\Python\Python35\lib\site-packages\tensorflow\python\estimator\estimator.py"", line 763, in _call_input_fn
    input_fn_args = util.fn_args(input_fn)
  File ""C:\Users\5V\AppData\Local\Programs\Python\Python35\lib\site-packages\tensorflow\python\estimator\util.py"", line 55, in fn_args
    args = tf_inspect.getfullargspec(fn).args
  File ""C:\Users\5V\AppData\Local\Programs\Python\Python35\lib\site-packages\tensorflow\python\util\tf_inspect.py"", line 67, in getfullargspec
    if d.decorator_argspec is not None), spec_fn(target))
  File ""C:\Users\5V\AppData\Local\Programs\Python\Python35\lib\inspect.py"", line 1095, in getfullargspec
    raise TypeError('unsupported callable') from ex
TypeError: unsupported callable
